Workbook

Sheet README
A1: Private credit, AI-SPV and repo contagion stress model
A2: Built for the Proteo Markets post The Six-Point Cliff. 24 institutions (13 US, 10 non-US, Jefferies). USD bn. Inputs as of 19 Oct 2026: CET1 and RWA of the 12 US banks that had reported at 30-Sep-2026, other balance-sheet items at 30-Jun-2026 unless noted; listed BDC P/NAV at 19-Oct-2026 prices.
A3: What it does
A4: 1. Models each risk on its own (11 modules, Modules sheet), per bank, from filings: back-leverage to private-credit intermediaries with a look-through to the junk loans they hold (M1, BDC + BDC_EAD + CreditEngine), fund finance (M2), structured-entity / ABF lending (M3), PE-owned insurers (M4), AI / GPU / data-centre SPVs with chip obsolescence (M5, AI_Deals), trading and HFS marks (M6), CRE (M7), rates incl. forced HTM sales (M8), loss of SRT relief (M9), written sub-IG TRS (M10), prime / margin gap risk (M11).
A5: 2. Connects banks through the repo and funding markets (Contagion sheet, 8 rounds): capital loss -> rating notches -> contractual triggers, deposit / wholesale / MMF CP run-off, repo haircut add-ons and non-rollover of inventory repo -> liquidity shortfall -> forced asset sales; MMF withdrawal of private-collateral repo -> matched-book clients forced to sell; BDC / private-credit funds and insurers sell into the same markets -> price impact by asset class -> re-marks of every bank's holdings and of private-credit pools behind back-leverage -> interbank losses when a bank defaults (max-entropy network).
A6: 2b. Panic / information contagion: every round the street reads public news (BDC coverage breaches, private-credit price discount, G-SIB downgrades and MDA breaches, any failure) and sets a panic intensity S (0-1). S pushes the credit factor down (credit crunch), widens spreads, moves private-credit marks to market, makes funds sell and redeem, triggers runs on the weakest-ranked banks and in wholesale / CP / repo funding, and applies a common panic discount to every risky asset class at once (correlations -> 1). Flight-to-quality deposits go to the strongest half.
A7: 3. Rerating tests: rating migration of the underlying loans (S&P average vs Moody's 2009 matrices) cuts borrowing bases and forces BDC sales; BDCs losing IG draw their bank revolvers in full; bank downgrades drive runs.
A8: 4. Monte Carlo (10,000 joint draws, Student-t fat tails with a crisis regime in which correlations go to 0.95, panic on, conditioned on today), probability ladder and trigger-conditional probabilities (Fat_Tails), reverse stress and an each-module-alone grid, computed by engine.py (Python mirror of these formulas) and written to MC_Summary, MC_Distribution, Reverse_Stress and Standalone_Grid as values. Checks proves the Excel formulas reproduce the Python engine for the active scenario.
A9: How to use
A10: Dashboard!C4: pick a scenario. Scenarios sheet: edit the yellow Custom column (or any blue value); sw_M1..sw_M11 switch modules off; fs_on / ib_on / liq_on switch contagion channels off. Every bank input is on Inputs_Banks / Holdings / BDC / BDC_EAD / AI_Deals with its source on Sources.
A11: To refresh Monte Carlo / reverse stress after changing inputs: save in Excel, then run python engine.py Private_Credit_Contagion_Model.xlsx (prints all scenarios) or python post.py <file> (rewrites the value sheets). post.py needs LibreOffice for its recalculation step.
A12: Sheet map
... A15: Bank-level private-credit, AI and BDC facility holdings are partly estimates (orange). Call-report business-credit-intermediary (BCI) loans are treated as back-leverage on junk pools: conservative for banks whose book is mostly IG fund lending (State Street in particular). BofA's $49.9bn written sub-IG TRS is treated as financing with an 80% advance (interpretation unresolved). Price-impact coefficients for illiquid credit, run-off rates and the Monte Carlo lever mappings are judgment, documented on Scenarios / Holdings / MC_Summary. No PPNR credit in named scenarios (instantaneous marks). Probabilities are model-conditional, not forecasts.

Sheet Dashboard
A1: Private credit, AI-SPV and repo contagion stress model - 24 banks
A2: As of 19 Oct 2026. Pick a scenario in C4 (or edit the Custom column on Scenarios). USD bn.
B4: Active scenario | C4: 2008-combined | E4: <- choose: Baseline, Software/AI repricing, GPU obsolescence, Credit 2009, Rerating cascade, Repo run, Rates shock, 2008-combined, Panic cascade, Custom
B6: SYSTEM | H6: MONTE CARLO, 3-yr horizon: fat tails + panic, conditioned on today (see MC_Summary, Fat_Tails) | L6: Backstop ON | M6: Backstop OFF
B7: Standalone loss, all banks ($bn) | F7: =Results!B33 -> 748.90712 | H7: =MC_Summary!A5 -> P(systemic: >=3 G-SIBs < MDA or any G-SIB default) | L7: =MC_Summary!B5 -> 0.0997 | M7: =MC_Summary!C5 -> 0.12
B8: Final loss, all banks ($bn) | F8: =Results!B34 -> 1465.0937 | H8: =MC_Summary!A6 -> P(>=1 G-SIB below MDA) | L8: =MC_Summary!B6 -> 0.1014 | M8: =MC_Summary!C6 -> 0.1251
B9: Contagion amplification (final / standalone) | F9: =Results!B35 -> 1.956309 | H9: =MC_Summary!A7 -> P(>=3 G-SIBs below MDA) | L9: =MC_Summary!B7 -> 0.0997 | M9: =MC_Summary!C7 -> 0.12
B10: G-SIBs below MDA | F10: =Results!B36 -> 18 | H10: =MC_Summary!A8 -> P(>=1 G-SIB below 4.5% minimum) | L10: =MC_Summary!B8 -> 0.0767 | M10: =MC_Summary!C8 -> 0.1053
B11: G-SIBs below 4.5% minimum | F11: =Results!B37 -> 11 | H11: =MC_Summary!A9 -> P(any institution in default / resolution) | L11: =MC_Summary!B9 -> 0.0766 | M11: =MC_Summary!C9 -> 0.1098
B12: Institutions in default / resolution | F12: =Results!B38 -> 14
B13: Capital shortfall to MDA, all banks ($bn) | F13: =Results!B39 -> 1192.2265 | H13: REVERSE STRESS (joint factor, no earnings credit; see Reverse_Stress) | L13: z | M13: Pool mark
B14: Liquidity shortfall, all banks ($bn) | F14: =Results!B40 -> 1693.2005 | H14: First G-SIB below MDA | L14: =Reverse_Stress!B108 -> -0.875 | M14: =Reverse_Stress!C108 -> 0.84612651
B15: SYSTEMIC (>=3 G-SIBs below MDA or any G-SIB in default) | F15: =Results!B41 -> YES | H15: Systemic (>=3 G-SIBs below MDA) | L15: =Reverse_Stress!D108 -> -1 | M15: =Reverse_Stress!E108 -> 0.8206049
B16: Total forced sales, all sellers ($bn) | F16: =Results!B42 -> 2113.5618 | H16: First G-SIB below 4.5% minimum | L16: =Reverse_Stress!F108 -> -1.125 | M16: =Reverse_Stress!G108 -> 0.7943519
B17: BDCs losing IG / below 150% coverage (standalone) | F17: =Results!B43 -> 34 / 33 | H17: First default / resolution | L17: =Reverse_Stress!H108 -> -1.125 | M17: =Reverse_Stress!I108 -> 0.7943519
B18: Generic private-credit pool value, final round (hold) | F18: =Results!B44 -> 0.40814662 | H18: Backstop ON row shown; OFF row on Reverse_Stress.
B19: Pool 3-yr PD, generic / software (final round) | F19: =Results!B45 -> 79.1% / 92.4% | H19: P(>=1 G-SIB below 4.5%) by horizon (constant hazard)
B20: PANIC INTENSITY S, final round (0-1) | F20: =Results!B46 -> 1 | H20: 1 year | L20: =1-(1-MC_Summary!B8)^(1/3) -> 0.026249683 | M20: =1-(1-MC_Summary!C8)^(1/3) -> 0.036409568
B21: Panic path, rounds 1..8 | F21: =Results!B47 -> 100% > 100% > 100% > 100% > 100% > 100% > 100% > 100% | H21: 3 months | L21: =1-(1-MC_Summary!B8)^(1/12) -> 0.0066280263 | M21: =1-(1-MC_Summary!C8)^(1/12) -> 0.0092293798
B23: Legend: blue = input, black = formula, green = link to another sheet, orange fill = estimate / proxy, yellow = choose / edit. USD bn. Ratios = CET1 / stressed RWA.
B25: Id | C25: Institution | D25: CET1 now | E25: Req. | F25: After standalone | G25: Final | H25: Status | I25: Standalone loss | J25: Final loss | K25: Liquidity shortfall | L25: Notches
B26: =Results!A6 -> JPM | C26: =Results!B6 -> JPMorgan | D26: =Results!D6 -> 0.13927181 | E26: =Results!E6 -> 0.115 | F26: =Results!G6 -> 0.090560708 | G26: =Results!I6 -> 0.057992627 | H26: =Results!L6 -> MDA breach | I26: =Results!F6 -> 90.54155 | J26: =Results!H6 -> 167.34295 | K26: =Results!O6 -> 0 | L26: =Results!M6 -> 4
B27: =Results!A7 -> BAC | C27: =Results!B7 -> Bank of America | D27: =Results!D7 -> 0.10877789 | E27: =Results!E7 -> 0.1 | F27: =Results!G7 -> 0.063912327 | G27: =Results!I7 -> 0.026950106 | H27: =Results!L7 -> Below minimum | I27: =Results!F7 -> 72.504731 | J27: =Results!H7 -> 145.31336 | K27: =Results!O7 -> 280.44922 | L27: =Results!M7 -> 6
B28: =Results!A8 -> C | C28: =Results!B8 -> Citigroup | D28: =Results!D8 -> 0.12777011 | E28: =Results!E8 -> 0.116 | F28: =Results!G8 -> 0.074774286 | G28: =Results!I8 -> 0.040234798 | H28: =Results!L8 -> Below minimum | I28: =Results!F8 -> 57.916402 | J28: =Results!H8 -> 103.86953 | K28: =Results!O8 -> 263.57463 | L28: =Results!M8 -> 6
B29: =Results!A9 -> WFC | C29: =Results!B9 -> Wells Fargo | D29: =Results!D9 -> 0.10046276 | E29: =Results!E9 -> 0.085 | F29: =Results!G9 -> 0.042444949 | G29: =Results!I9 -> 0.0020739028 | H29: =Results!L9 -> Below minimum | I29: =Results!F9 -> 73.182838 | J29: =Results!H9 -> 131.5991 | K29: =Results!O9 -> 326.58085 | L29: =Results!M9 -> 6
B30: =Results!A10 -> GS | C30: =Results!B10 -> Goldman Sachs | D30: =Results!D10 -> 0.12411261 | E30: =Results!E10 -> 0.114 | F30: =Results!G10 -> 0.060409672 | G30: =Results!I10 -> 0.010515679 | H30: =Results!L10 -> Below minimum | I30: =Results!F10 -> 48.096922 | J30: =Results!H10 -> 92.121385 | K30: =Results!O10 -> 0 | L30: =Results!M10 -> 6
B31: =Results!A11 -> MS | C31: =Results!B11 -> Morgan Stanley | D31: =Results!D11 -> 0.1490433 | E31: =Results!E11 -> 0.118 | F31: =Results!G11 -> 0.07461862 | G31: =Results!I11 -> 0.018967748 | H31: =Results!L11 -> Below minimum | I31: =Results!F11 -> 40.785604 | J31: =Results!H11 -> 76.594937 | K31: =Results!O11 -> 0 | L31: =Results!M11 -> 6
B32: =Results!A12 -> PNC | C32: =Results!B12 -> PNC | D32: =Results!D12 -> 0.098043131 | E32: =Results!E12 -> 0.07 | F32: =Results!G12 -> 0.037635245 | G32: =Results!I12 -> 0.0036018265 | H32: =Results!L12 -> Below minimum | I32: =Results!F12 -> 28.744451 | J32: =Results!H12 -> 47.151902 | K32: =Results!O12 -> 71.598487 | L32: =Results!M12 -> 6
B33: =Results!A13 -> USB | C33: =Results!B13 -> U.S. Bancorp | D33: =Results!D13 -> 0.10822511 | E33: =Results!E13 -> 0.071 | F33: =Results!G13 -> 0.074607178 | G33: =Results!I13 -> 0.050903962 | H33: =Results!L13 -> MDA breach | I33: =Results!F13 -> 14.051402 | J33: =Results!H13 -> 27.061055 | K33: =Results!O13 -> 0 | L33: =Results!M13 -> 3
B34: =Results!A14 -> TFC | C34: =Results!B14 -> Truist | D34: =Results!D14 -> 0.10722557 | E34: =Results!E14 -> 0.07 | F34: =Results!G14 -> 0.051950612 | G34: =Results!I14 -> 0.015729221 | H34: =Results!L14 -> Below minimum | I34: =Results!F14 -> 22.073144 | J34: =Results!H14 -> 38.964772 | K34: =Results!O14 -> 74.570633 | L34: =Results!M14 -> 6
B35: =Results!A15 -> STT | C35: =Results!B15 -> State Street | D35: =Results!D15 -> 0.10953058 | E35: =Results!E15 -> 0.08 | F35: =Results!G15 -> -0.011077412 | G35: =Results!I15 -> -0.11290916 | H35: =Results!L15 -> Insolvent | I35: =Results!F15 -> 17.082083 | J35: =Results!H15 -> 32.54503 | K35: =Results!O15 -> 116.96806 | L35: =Results!M15 -> 6
B36: =Results!A16 -> BK | C36: =Results!B16 -> BNY | D36: =Results!D16 -> 0.10948905 | E36: =Results!E16 -> 0.085 | F36: =Results!G16 -> 0.07119447 | G36: =Results!I16 -> 0.033469555 | H36: =Results!L16 -> Below minimum | I36: =Results!F16 -> 6.2524927 | J36: =Results!H16 -> 14.066982 | K36: =Results!O16 -> 85.534064 | L36: =Results!M16 -> 6
B37: =Results!A17 -> FCNCA | C37: =Results!B17 -> First Citizens | D37: =Results!D17 -> 0.10771939 | E37: =Results!E17 -> 0.07 | F37: =Results!G17 -> 0.067473721 | G37: =Results!I17 -> 0.059496066 | H37: =Results!L17 -> MDA breach | I37: =Results!F17 -> 6.4328991 | J37: =Results!H17 -> 8.0233884 | K37: =Results!O17 -> 0 | L37: =Results!M17 -> 2
... B49: =Results!A29 -> JEF | C49: =Results!B29 -> Jefferies | D49: =Results!D29 -> 0.09 | E49: =Results!E29 -> 0.0675 | F49: =Results!G29 -> 0.072274665 | G49: =Results!I29 -> 0.054936025 | H49: =Results!L29 -> MDA breach | I49: =Results!F29 -> 1.1569136 | J49: =Results!H29 -> 2.9708128 | K49: =Results!O29 -> 1.8886978 | L49: =Results!M29 -> 2

Sheet Scenarios
A1: Scenario parameters
A2: Columns E-N = scenario values (blue inputs; Custom in yellow is free to edit). Column O = active value used by every formula (named p_<key>). Select the scenario on Dashboard!C4.
A4: Key | B4: Group | C4: Description | D4: Unit | E4: Baseline | F4: Software/AI repricing | G4: GPU obsolescence | H4: Credit 2009 | I4: Rerating cascade | J4: Repo run | K4: Rates shock | L4: 2008-combined | M4: Panic cascade | N4: Custom | O4: ACTIVE | P4: Basis / source
A5: z | B5: Credit pool | C5: Systematic credit factor (3-yr horizon; negative = bad) | D5: z | E5: 0 | F5: -1 | G5: -0.5 | H5: -2 | I5: -1 | J5: -0.5 | K5: -0.5 | L5: -2.5 | M5: -1 | N5: -2.5 | O5: =INDEX($E5:$N5,1,MATCH(sel_scen,$E$4:$N$4,0)) -> -2.5 | P5: Vasicek one-factor. z=-2.0 reproduces S&P 2000-02 3-yr cumulative B/B- defaults (32.7%/45.0%) with rho=0.20
A6: hid | B6: Credit pool | C6: Hidden-default add-on to 3-yr PD (shadow defaults not yet recognised) | D6: frac | E6: 0 | F6: 0.02 | G6: 0 | H6: 0.03 | I6: 0.02 | J6: 0 | K6: 0 | L6: 0.062 | M6: 0.02 | N6: 0.062 | O6: =INDEX($E6:$N6,1,MATCH(sel_scen,$E$4:$N$4,0)) -> 0.062 | P6: Lincoln bad-PIK 6.2% of loans (Q2-26) = upper bound of defaults masked by PIK/extensions
A7: m_sw | B7: Credit pool | C7: Software sub-pool PD multiplier (AI disruption) | D7: x | E7: 1 | F7: 2 | G7: 1.5 | H7: 1.25 | I7: 1.5 | J7: 1 | K7: 1 | L7: 2 | M7: 1.5 | N7: 2 | O7: =INDEX($E7:$N7,1,MATCH(sel_scen,$E$4:$N$4,0)) -> 2 | P7: Judgment; Fitch software PCDR only 0.6% today but distressed software marks 50-65
A8: lgd_gen | B8: Credit pool | C8: LGD, generic direct-lending loans | D8: frac | E8: 0.35 | F8: 0.4 | G8: 0.35 | H8: 0.5 | I8: 0.4 | J8: 0.35 | K8: 0.35 | L8: 0.5 | M8: 0.4 | N8: 0.5 | O8: =INDEX($E8:$N8,1,MATCH(sel_scen,$E$4:$N$4,0)) -> 0.5 | P8: 1L/unitranche recovery 65% base, 50% stress (Moody's 2009 1L price 54%)
A9: lgd_sw | B9: Credit pool | C9: LGD, software / ARR loans | D9: frac | E9: 0.5 | F9: 0.65 | G9: 0.55 | H9: 0.65 | I9: 0.6 | J9: 0.5 | K9: 0.5 | L9: 0.7 | M9: 0.6 | N9: 0.7 | O9: =INDEX($E9:$N9,1,MATCH(sel_scen,$E$4:$N$4,0)) -> 0.7 | P9: Small/mid software recovery 20-40% in stress (Zito via WSJ/Bloomberg)
A10: ds | B10: Credit pool | C10: Spread widening on performing loans | D10: bp | E10: 0 | F10: 150 | G10: 75 | H10: 600 | I10: 250 | J10: 150 | K10: 50 | L10: 700 | M10: 250 | N10: 700 | O10: =INDEX($E10:$N10,1,MATCH(sel_scen,$E$4:$N$4,0)) -> 700 | P10: Software sub-index -7.5 pts YTD Feb-26; 2008 LLI low 60.33. Spread duration 3 yrs (CDLI life 3.2)
A11: ds_sw | B11: Credit pool | C11: Extra spread widening, software loans | D11: bp | E11: 0 | F11: 300 | G11: 150 | H11: 200 | I11: 150 | J11: 0 | K11: 0 | L11: 300 | M11: 150 | N11: 300 | O11: =INDEX($E11:$N11,1,MATCH(sel_scen,$E$4:$N$4,0)) -> 300 | P11: Judgment: software performing bids 87.6 (Feb-26) vs index 94.6
A12: gap | B12: Credit pool | C12: Valuation gap: carrying marks overstate value by | D12: frac | E12: 0 | F12: 0.03 | G12: 0 | H12: 0.05 | I12: 0.03 | J12: 0.02 | K12: 0 | L12: 0.1 | M12: 0.03 | N12: 0.1 | O12: =INDEX($E12:$N12,1,MATCH(sel_scen,$E$4:$N$4,0)) -> 0.1 | P12: Same loan marked ~10 vs ~100 across lenders; market-implied marks 78-98
A13: w_mkt | B13: Credit pool | C13: Weight on market-implied BDC marks (P/NAV) | D13: frac | E13: 0 | F13: 0.5 | G13: 0.25 | H13: 1 | I13: 0.5 | J13: 1 | K13: 0.25 | L13: 1 | M13: 0.5 | N13: 1 | O13: =INDEX($E13:$N13,1,MATCH(sel_scen,$E$4:$N$4,0)) -> 1 | P13: Listed BDC P/NAV 6-Oct-26; non-traded use listed asset-weighted average
A14: phi | B14: Credit pool | C14: Share of SPV facilities enforced / liquidated now (vs worked out) | D14: frac | E14: 0.1 | F14: 0.3 | G14: 0.2 | H14: 0.5 | I14: 0.4 | J14: 0.6 | K14: 0.2 | L14: 0.8 | M14: 0.4 | N14: 0.8 | O14: =INDEX($E14:$N14,1,MATCH(sel_scen,$E$4:$N$4,0)) -> 0.8 | P14: JPM market-value SPVs cure in 2 business days (OSCF EX-10)
A15: c_liq | B15: Credit pool | C15: Liquidation cost on enforced pools | D15: frac | E15: 0.02 | F15: 0.03 | G15: 0.02 | H15: 0.05 | I15: 0.03 | J15: 0.05 | K15: 0.02 | L15: 0.05 | M15: 0.03 | N15: 0.05 | O15: =INDEX($E15:$N15,1,MATCH(sel_scen,$E$4:$N$4,0)) -> 0.05 | P15: Judgment
A16: a_spv | B16: Credit pool | C16: SPV advance rate (back-leverage, vs current pool value) | D16: frac | E16: 0.7 | F16: 0.7 | G16: 0.7 | H16: 0.7 | I16: 0.7 | J16: 0.7 | K16: 0.7 | L16: 0.7 | M16: 0.7 | N16: 0.75 | O16: =INDEX($E16:$N16,1,MATCH(sel_scen,$E$4:$N$4,0)) -> 0.7 | P16: SPV EX-10 first-lien 60-75%, MM 1L 65-72.5%
... A70: lgd_ib | B70: Contagion | C70: Loss on unsecured interbank claims to a failed bank | D70: frac | E70: 0.05 | F70: 0.05 | G70: 0.05 | H70: 0.1 | I70: 0.1 | J70: 0.2 | K70: 0.1 | L70: 0.4 | M70: 0.1 | N70: 0.4 | O70: =INDEX($E70:$N70,1,MATCH(sel_scen,$E$4:$N$4,0)) -> 0.4 | P70: SPOE resolution ~0-5%; Lehman-style 40%+
A71: fs_on | B71: Switches | C71: Fire-sale contagion on (1/0) | D71: 0/1 | E71: 1 | F71: 1 | G71: 1 | H71: 1 | I71: 1 | J71: 1 | K71: 1 | L71: 1 | M71: 1 | N71: 1 | O71: =INDEX($E71:$N71,1,MATCH(sel_scen,$E$4:$N$4,0)) -> 1
A72: ib_on | B72: Switches | C72: Interbank default contagion on (1/0) | D72: 0/1 | E72: 1 | F72: 1 | G72: 1 | H72: 1 | I72: 1 | J72: 1 | K72: 1 | L72: 1 | M72: 1 | N72: 1 | O72: =INDEX($E72:$N72,1,MATCH(sel_scen,$E$4:$N$4,0)) -> 1
A73: liq_on | B73: Switches | C73: Liquidity / run channel on (1/0) | D73: 0/1 | E73: 1 | F73: 1 | G73: 1 | H73: 1 | I73: 1 | J73: 1 | K73: 1 | L73: 1 | M73: 1 | N73: 1 | O73: =INDEX($E73:$N73,1,MATCH(sel_scen,$E$4:$N$4,0)) -> 1
A74: sw_M1 | B74: Switches | C74: Module M1 on (1/0) | D74: 0/1 | E74: 1 | F74: 1 | G74: 1 | H74: 1 | I74: 1 | J74: 1 | K74: 1 | L74: 1 | M74: 1 | N74: 1 | O74: =INDEX($E74:$N74,1,MATCH(sel_scen,$E$4:$N$4,0)) -> 1
A75: sw_M2 | B75: Switches | C75: Module M2 on (1/0) | D75: 0/1 | E75: 1 | F75: 1 | G75: 1 | H75: 1 | I75: 1 | J75: 1 | K75: 1 | L75: 1 | M75: 1 | N75: 1 | O75: =INDEX($E75:$N75,1,MATCH(sel_scen,$E$4:$N$4,0)) -> 1
A76: sw_M3 | B76: Switches | C76: Module M3 on (1/0) | D76: 0/1 | E76: 1 | F76: 1 | G76: 1 | H76: 1 | I76: 1 | J76: 1 | K76: 1 | L76: 1 | M76: 1 | N76: 1 | O76: =INDEX($E76:$N76,1,MATCH(sel_scen,$E$4:$N$4,0)) -> 1
A77: sw_M4 | B77: Switches | C77: Module M4 on (1/0) | D77: 0/1 | E77: 1 | F77: 1 | G77: 1 | H77: 1 | I77: 1 | J77: 1 | K77: 1 | L77: 1 | M77: 1 | N77: 1 | O77: =INDEX($E77:$N77,1,MATCH(sel_scen,$E$4:$N$4,0)) -> 1
A78: sw_M5 | B78: Switches | C78: Module M5 on (1/0) | D78: 0/1 | E78: 1 | F78: 1 | G78: 1 | H78: 1 | I78: 1 | J78: 1 | K78: 1 | L78: 1 | M78: 1 | N78: 1 | O78: =INDEX($E78:$N78,1,MATCH(sel_scen,$E$4:$N$4,0)) -> 1
A79: sw_M6 | B79: Switches | C79: Module M6 on (1/0) | D79: 0/1 | E79: 1 | F79: 1 | G79: 1 | H79: 1 | I79: 1 | J79: 1 | K79: 1 | L79: 1 | M79: 1 | N79: 1 | O79: =INDEX($E79:$N79,1,MATCH(sel_scen,$E$4:$N$4,0)) -> 1
A80: sw_M7 | B80: Switches | C80: Module M7 on (1/0) | D80: 0/1 | E80: 1 | F80: 1 | G80: 1 | H80: 1 | I80: 1 | J80: 1 | K80: 1 | L80: 1 | M80: 1 | N80: 1 | O80: =INDEX($E80:$N80,1,MATCH(sel_scen,$E$4:$N$4,0)) -> 1
A81: sw_M8 | B81: Switches | C81: Module M8 on (1/0) | D81: 0/1 | E81: 1 | F81: 1 | G81: 1 | H81: 1 | I81: 1 | J81: 1 | K81: 1 | L81: 1 | M81: 1 | N81: 1 | O81: =INDEX($E81:$N81,1,MATCH(sel_scen,$E$4:$N$4,0)) -> 1
A82: sw_M9 | B82: Switches | C82: Module M9 on (1/0) | D82: 0/1 | E82: 1 | F82: 1 | G82: 1 | H82: 1 | I82: 1 | J82: 1 | K82: 1 | L82: 1 | M82: 1 | N82: 1 | O82: =INDEX($E82:$N82,1,MATCH(sel_scen,$E$4:$N$4,0)) -> 1
... A84: sw_M11 | B84: Switches | C84: Module M11 on (1/0) | D84: 0/1 | E84: 1 | F84: 1 | G84: 1 | H84: 1 | I84: 1 | J84: 1 | K84: 1 | L84: 1 | M84: 1 | N84: 1 | O84: =INDEX($E84:$N84,1,MATCH(sel_scen,$E$4:$N$4,0)) -> 1
A85: panic_on | B85: Panic | C85: Panic / information contagion on (1/0) | D85: 0/1 | E85: 1 | F85: 1 | G85: 1 | H85: 1 | I85: 1 | J85: 1 | K85: 1 | L85: 1 | M85: 1 | N85: 1 | O85: =INDEX($E85:$N85,1,MATCH(sel_scen,$E$4:$N$4,0)) -> 1 | P85: Off reproduces the version without panic
A86: S0 | B86: Panic | C86: Panic intensity at the start (0-1): the market state today | D86: frac | E86: 0.1 | F86: 0.15 | G86: 0.15 | H86: 0.2 | I86: 0.15 | J86: 0.3 | K86: 0.15 | L86: 0.3 | M86: 0.25 | N86: 0.3 | O86: =INDEX($E86:$N86,1,MATCH(sel_scen,$E$4:$N$4,0)) -> 0.3 | P86: 7-Oct-26: European banks -4 to -6% on the day, US bank and alt-manager stocks -10 to -28% from 3-month highs, but VIX 15.7, HY and loan ETFs within 1-3% of highs (Yahoo prices)
A87: news0 | B87: Panic | C87: Exogenous news already public (gate breaches, headlines), news units | D87: x | E87: 0.05 | F87: 0.05 | G87: 0.05 | H87: 0.05 | I87: 0.05 | J87: 0.1 | K87: 0.05 | L87: 0.1 | M87: 0.25 | N87: 0.25 | O87: =INDEX($E87:$N87,1,MATCH(sel_scen,$E$4:$N$4,0)) -> 0.1 | P87: Q3 tender requests above 2x the 5% gate at OCIC, ADS, HLEND, ASIF, OTIC (39%), NHPIF; Panic cascade adds a gate break + bank downgrade headlines
A88: zc | B88: Panic | C88: Credit-crunch feedback: fall in the credit factor at full panic | D88: z | E88: 0.75 | F88: 0.75 | G88: 0.75 | H88: 0.75 | I88: 0.75 | J88: 0.75 | K88: 0.75 | L88: 0.75 | M88: 0.75 | N88: 0.75 | O88: =INDEX($E88:$N88,1,MATCH(sel_scen,$E$4:$N$4,0)) -> 0.75 | P88: Judgment: refinancing window shuts for B/CCC borrowers in panic
A89: ds_pan | B89: Panic | C89: Extra spread widening on performing loans at full panic | D89: bp | E89: 400 | F89: 400 | G89: 400 | H89: 400 | I89: 400 | J89: 400 | K89: 400 | L89: 400 | M89: 400 | N89: 400 | O89: =INDEX($E89:$N89,1,MATCH(sel_scen,$E$4:$N$4,0)) -> 400 | P89: Judgment: March 2020 loan index fell to 76.23
A90: u_pan_all | B90: Panic | C90: Extra uninsured-deposit run-off at full panic, all banks | D90: frac | E90: 0.05 | F90: 0.05 | G90: 0.05 | H90: 0.05 | I90: 0.05 | J90: 0.05 | K90: 0.05 | L90: 0.05 | M90: 0.05 | N90: 0.05 | O90: =INDEX($E90:$N90,1,MATCH(sel_scen,$E$4:$N$4,0)) -> 0.05 | P90: Judgment
A91: u_pan_weak | B91: Panic | C91: Extra run-off at full panic for banks the street sees as weak | D91: frac | E91: 0.2 | F91: 0.2 | G91: 0.2 | H91: 0.2 | I91: 0.2 | J91: 0.2 | K91: 0.2 | L91: 0.2 | M91: 0.2 | N91: 0.2 | O91: =INDEX($E91:$N91,1,MATCH(sel_scen,$E$4:$N$4,0)) -> 0.2 | P91: SVB ~25% of deposits in one day; Twitter attention amplified run severity (Cookson et al. 2023)
A92: w_pan | B92: Panic | C92: Extra wholesale non-rollover at full panic | D92: frac | E92: 0.4 | F92: 0.4 | G92: 0.4 | H92: 0.4 | I92: 0.4 | J92: 0.4 | K92: 0.4 | L92: 0.4 | M92: 0.4 | N92: 0.4 | O92: =INDEX($E92:$N92,1,MATCH(sel_scen,$E$4:$N$4,0)) -> 0.4 | P92: Judgment
A93: cp_pan | B93: Panic | C93: Extra prime-MMF CP/CD non-rollover at full panic | D93: frac | E93: 0.5 | F93: 0.5 | G93: 0.5 | H93: 0.5 | I93: 0.5 | J93: 0.5 | K93: 0.5 | L93: 0.5 | M93: 0.5 | N93: 0.5 | O93: =INDEX($E93:$N93,1,MATCH(sel_scen,$E$4:$N$4,0)) -> 0.5 | P93: Judgment
A94: pull_pan | B94: Panic | C94: Extra MMF withdrawal of other-collateral repo at full panic | D94: frac | E94: 0.5 | F94: 0.5 | G94: 0.5 | H94: 0.5 | I94: 0.5 | J94: 0.5 | K94: 0.5 | L94: 0.5 | M94: 0.5 | N94: 0.5 | O94: =INDEX($E94:$N94,1,MATCH(sel_scen,$E$4:$N$4,0)) -> 0.5 | P94: Judgment (2008 tri-party run on quantity)
A95: dh_pan | B95: Panic | C95: Extra haircut on non-govt repo at full panic | D95: frac | E95: 0.1 | F95: 0.1 | G95: 0.1 | H95: 0.1 | I95: 0.1 | J95: 0.1 | K95: 0.1 | L95: 0.1 | M95: 0.1 | N95: 0.1 | O95: =INDEX($E95:$N95,1,MATCH(sel_scen,$E$4:$N$4,0)) -> 0.1 | P95: CGFS 36 2007-09 haircut rises
...

Sheet Globals
A1: Global constants (not scenario-dependent)
A2: Blue = input. Each constant is a named range g_<key> used in formulas.
A4: Key | B4: Value | C4: Description / basis
A5: rho | B5: 0.2 | C5: Asset correlation, private-credit pool (Basel corporate range 0.12-0.24)
A6: rho_ai | B6: 0.3 | C6: Asset correlation, AI names (concentrated sector) - judgment
A7: lgd_gen_b | B7: 0.35 | C7: Base-case LGD embedded in carrying values (generic)
A8: lgd_sw_b | B8: 0.5 | C8: Base-case LGD embedded in carrying values (software)
A9: dur_s | B9: 3 | C9: Spread duration of performing direct loans (CDLI effective life 3.2 yrs)
A10: lgd_lp | B10: 0.3 | C10: LGD on defaulted LP commitments (sub lines) - judgment
A11: nav_share | B11: 0.15 | C11: NAV-loan share of fund finance - judgment (FSB: sub lines dominate)
A12: nav_ltv | B12: 0.2 | C12: NAV-loan LTV (Nodem avg ~14%, mostly <=20%; FSB <=30%)
A13: tail_share | B13: 0.2 | C13: Share of NAV loans to tail funds
A14: tail_mult | B14: 2.5 | C14: NAV decline multiple for tail funds
A15: a_abf | B15: 0.8 | C15: Advance rate on ABF / SE senior warehouses - judgment
A16: lgd_ins | B16: 0.4 | C16: LGD on insurer facilities / FA-backed repo (wrong-way) - judgment
... A43: fabr | B43: 27.3 | C43: FA-backed repo outstanding Jun-26 (Fed EFA)

Sheet Inputs_Banks
A1: Per-bank inputs (USD bn; CET1 and RWA of US banks at 30-Sep-2026, other items 30-Jun-2026 unless noted)
A2: Blue = sourced input; orange fill = estimate / proxy (see Sources sheet for every cell); black = formula. FX: EUR 1.1417, GBP 1.3259, JPY 1/162.61, CAD 1/1.4205.
A5: Id | B5: Institution | C5: Report ccy | D5: G-SIB (1/0) | E5: AFS/OCI in CET1 (1/0) | F5: Notches to HY | G5: CET1 ($bn) | H5: RWA ($bn) | I5: CET1 req. incl. buffers (MDA) | J5: PPNR / quarter ($bn) | K5: AFS / FVOCI debt FV ($bn) | L5: AFS unrealised loss ($bn) | M5: HTM / AC book ($bn) | N5: HTM unrealised loss ($bn) | O5: AFS net duration (yrs) | P5: Strategic equities ($bn) | Q5: Back-leverage drawn ($bn) | R5: Back-leverage undrawn ($bn) | S5: Fund finance drawn ($bn) | T5: Fund finance undrawn ($bn) | U5: ABF / SE residual drawn ($bn) | V5: ABF / SE residual undrawn ($bn) | W5: Named-BDC facilities drawn ($bn) | X5: Named-BDC facilities committed ($bn) | Y5: Generic back-leverage drawn ($bn) | Z5: Generic back-leverage undrawn ($bn) | AA5: SRT CET1 relief (bp) | AB5: Prime / margin lending ($bn) | AC5: Written sub-IG TRS ($bn) | AD5: Facilities to insurers ($bn) | AE5: FA-backed repo ($bn) | AF5: CRE loans ($bn) | AG5: HQLA ($bn) | AH5: LCR | AI5: Uninsured / wholesale deposits ($bn) | AJ5: Total deposits ($bn) | AK5: ST unsecured wholesale ($bn) | AL5: Repo + sec. loaned ($bn) | AM5: Non-govt share of repo | AN5: Non-govt repo funding ($bn) | AO5: Prime-MMF CP/CD ($bn) | AP5: MMF repo, other collateral ($bn) | AQ5: CB-eligible capacity ($bn) | AR5: Downgrade outflow 0 notch ($bn) | AS5: Downgrade outflow 1 notch ($bn) | AT5: Downgrade outflow 2 notch ($bn) | AU5: Downgrade outflow 3 notch ($bn) | AV5: Downgrade outflow 4 notch ($bn) | AW5: Downgrade outflow 5 notch ($bn) | AX5: Downgrade outflow 6 notch ($bn) | AY5: Intra-fin. assets ($bn) | AZ5: Intra-fin. liabilities ($bn) | BA5: CET1 ratio now | BB5: Saleable non-HQLA holdings ($bn)
A6: JPM | B6: JPMorgan | C6: USD | D6: 1 | E6: 1 | F6: 5 | G6: 304.1 | H6: 2183.5 | I6: 0.115 | J6: 30.031 | K6: 536.048 | L6: -2.641 | M6: 268.474 | N6: -18.164 | O6: 2.5 | P6: 0 | Q6: 56.5 | R6: 23.1 | S6: 68 | T6: 37.6 | U6: 0 | V6: 0 | W6: =SUM(BDC_EAD!C$31:C$52)+SUM(BDC_EAD!C$81:C$102) -> 2.015715 | X6: =SUM(BDC_EAD!C$6:C$27)+SUM(BDC_EAD!C$56:C$77) -> 4.303613 | Y6: =MAX(0,Q6-W6) -> 54.484285 | Z6: =MAX(0,R6-(X6-W6)) -> 20.812102 | AA6: 0 | AB6: 82.203 | AC6: 0 | AD6: 0 | AE6: 4.55 | AF6: 180.31 | AG6: 975.412 | AH6: 1.1 | AI6: 1743.9 | AJ6: 2713.7 | AK6: 30.166 | AL6: 704.704 | AM6: 0.26699021 | AN6: =AL6*AM6 -> 188.14907 | AO6: 5.45 | AP6: 34.48 | AQ6: 457 | AR6: 0 | AS6: 0.104 | AT6: 0.408 | AU6: 0.612 | AV6: 0.918 | AW6: 1.224 | AX6: 1.53 | AY6: 533.281 | AZ6: 633.693 | BA6: =G6/H6 -> 0.13927181 | BB6: =Holdings!$P6 -> 480.27
A7: BAC | B7: Bank of America | C7: USD | D7: 1 | E7: 1 | F7: 4 | G7: 198.4 | H7: 1823.9 | I7: 0.1 | J7: 12.931 | K7: 348.54 | L7: -2.374 | M7: 505.799 | N7: -82.094 | O7: 2.5 | P7: 0 | Q7: 31.5 | R7: 6.1 | S7: 37.3 | T7: 31.5 | U7: 0 | V7: 0 | W7: =SUM(BDC_EAD!D$31:D$52)+SUM(BDC_EAD!D$81:D$102) -> 3.8291 | X7: =SUM(BDC_EAD!D$6:D$27)+SUM(BDC_EAD!D$56:D$77) -> 9.004882 | Y7: =MAX(0,Q7-W7) -> 27.6709 | Z7: =MAX(0,R7-(X7-W7)) -> 0.924218 | AA7: 0 | AB7: 0 | AC7: 49.867 | AD7: 0 | AE7: 4.55 | AF7: 83.31 | AG7: 684 | AH7: 1.12 | AI7: 899.7 | AJ7: 2025.124 | AK7: 59.979 | AL7: 332.218 | AM7: 0.17209185 | AN7: =AL7*AM7 -> 57.172009 | AO7: 27.98 | AP7: 7.87 | AQ7: 357 | AR7: 0 | AS7: 0.121 | AT7: 1.816 | AU7: 2.724 | AV7: 4.086 | AW7: 5.448 | AX7: 6.81 | AY7: 335.222 | AZ7: 200.993 | BA7: =G7/H7 -> 0.10877789 | BB7: =Holdings!$P7 -> 211.05
A8: C | B8: Citigroup | C8: USD | D8: 1 | E8: 1 | F8: 3 | G8: 157.4 | H8: 1231.9 | I8: 0.116 | J8: 10.551 | K8: 286.765 | L8: -1.084 | M8: 167.893 | N8: -10.369 | O8: 2.5 | P8: 0 | Q8: 51.4 | R8: 19.8 | S8: 9 | T8: 4.2 | U8: 10.6 | V8: 0 | W8: =SUM(BDC_EAD!E$31:E$52)+SUM(BDC_EAD!E$81:E$102) -> 2.388312 | X8: =SUM(BDC_EAD!E$6:E$27)+SUM(BDC_EAD!E$56:E$77) -> 5.348295 | Y8: =MAX(0,Q8-W8) -> 49.011688 | Z8: =MAX(0,R8-(X8-W8)) -> 16.840017 | AA8: 0 | AB8: 83.322 | AC8: 0 | AD8: 3 | AE8: 4.55 | AF8: 37.19 | AG8: 641.2 | AH8: 1.13 | AI8: 739.5 | AJ8: 1492.607 | AK8: 60.978 | AL8: 411.126 | AM8: 0.19404473 | AN8: =AL8*AM8 -> 79.776835 | AO8: 3.89 | AP8: 17.48 | AQ8: 163 | AR8: 0 | AS8: 0.2 | AT8: 0.4 | AU8: 0.6 | AV8: 0.9 | AW8: 1.2 | AX8: 1.5 | AY8: 297.956 | AZ8: 442.819 | BA8: =G8/H8 -> 0.12777011 | BB8: =Holdings!$P8 -> 198.5
A9: WFC | B9: Wells Fargo | C9: USD | D9: 1 | E9: 1 | F9: 3 | G9: 134.6 | H9: 1339.8 | I9: 0.085 | J9: 8.961 | K9: 250.326 | L9: -3.267 | M9: 198.573 | N9: -32.408 | O9: 2.5 | P9: 0 | Q9: 72 | R9: 36.2 | S9: 56.7 | T9: 27.6 | U9: 0 | V9: 0 | W9: =SUM(BDC_EAD!F$31:F$52)+SUM(BDC_EAD!F$81:F$102) -> 4.346347 | X9: =SUM(BDC_EAD!F$6:F$27)+SUM(BDC_EAD!F$56:F$77) -> 9.37608 | Y9: =MAX(0,Q9-W9) -> 67.653653 | Z9: =MAX(0,R9-(X9-W9)) -> 31.170267 | AA9: 0 | AB9: 0 | AC9: 0 | AD9: 2.6 | AE9: 4.55 | AF9: 126.02 | AG9: 414.24 | AH9: 1.19 | AI9: 786.2 | AJ9: 1501.405 | AK9: 25.168 | AL9: 251.804 | AM9: 0.19134785 | AN9: =AL9*AM9 -> 48.182155 | AO9: 12.67 | AP9: 17.2 | AQ9: 435.968 | AR9: 0 | AS9: 1.3666667 | AT9: 2.7333333 | AU9: 4.1 | AV9: 4.1 | AW9: 4.1 | AX9: 4.1 | AY9: 287.074 | AZ9: 163.988 | BA9: =G9/H9 -> 0.10046276 | BB9: =Holdings!$P9 -> 127.74
A10: GS | B10: Goldman Sachs | C10: USD | D10: 1 | E10: 1 | F10: 3 | G10: 101.4 | H10: 817 | I10: 0.114 | J10: 8.665 | K10: 155.636 | L10: -1 | M10: 74.658 | N10: -0.003 | O10: 2.5 | P10: 0 | Q10: 27.4 | R10: 15.5 | S10: 34.6 | T10: 14.6 | U10: 0 | V10: 0 | W10: =SUM(BDC_EAD!G$31:G$52)+SUM(BDC_EAD!G$81:G$102) -> 2.130358 | X10: =SUM(BDC_EAD!G$6:G$27)+SUM(BDC_EAD!G$56:G$77) -> 3.822584 | Y10: =MAX(0,Q10-W10) -> 25.269642 | Z10: =MAX(0,R10-(X10-W10)) -> 13.807774 | AA10: 0 | AB10: 145.84 | AC10: 0 | AD10: 0 | AE10: 4.55 | AF10: 40.31 | AG10: 454.349 | AH10: 1.26 | AI10: 214 | AJ10: 557.955 | AK10: 55.681 | AL10: 357.574 | AM10: 0.37173189 | AN10: =AL10*AM10 -> 132.92166 | AO10: 1.51 | AP10: 2.37 | AQ10: 379.39 | AR10: 0 | AS10: 0.165 | AT10: 1.778 | AU10: 2.667 | AV10: 4.0005 | AW10: 5.334 | AX10: 6.6675 | AY10: 400.09 | AZ10: 165.461 | BA10: =G10/H10 -> 0.12411261 | BB10: =Holdings!$P10 -> 366.97
A11: MS | B11: Morgan Stanley | C11: USD | D11: 1 | E11: 1 | F11: 4 | G11: 88.8 | H11: 595.8 | I11: 0.118 | J11: 7.446 | K11: 105.532 | L11: -2.229 | M11: 47.747 | N11: -7.509 | O11: 2.5 | P11: 0 | Q11: 20.9 | R11: 12.6 | S11: 12 | T11: 8.5 | U11: 0 | V11: 0 | W11: =SUM(BDC_EAD!H$31:H$52)+SUM(BDC_EAD!H$81:H$102) -> 2.651772 | X11: =SUM(BDC_EAD!H$6:H$27)+SUM(BDC_EAD!H$56:H$77) -> 5.792229 | Y11: =MAX(0,Q11-W11) -> 18.248228 | Z11: =MAX(0,R11-(X11-W11)) -> 9.459543 | AA11: 0 | AB11: 100.328 | AC11: 0 | AD11: 0 | AE11: 4.55 | AF11: 16.4 | AG11: 319.165 | AH11: 1.29 | AI11: 159.3 | AJ11: 446.068 | AK11: 9.4 | AL11: 152.757 | AM11: 0.45087003 | AN11: =AL11*AM11 -> 68.873553 | AO11: 0 | AP11: 0 | AQ11: 159.5825 | AR11: 0 | AS11: 0.427 | AT11: 0.875 | AU11: 1.3125 | AV11: 1.96875 | AW11: 2.625 | AX11: 3.28125 | AY11: 297.64 | AZ11: 120.379 | BA11: =G11/H11 -> 0.1490433 | BB11: =Holdings!$P11 -> 297.98
A12: PNC | B12: PNC | C12: USD | D12: 0 | E12: 0 | F12: 4 | G12: 49.1 | H12: 500.8 | I12: 0.07 | J12: 2.777 | K12: 71.1 | L12: -2.107 | M12: 78.406 | N12: -2.884 | O12: 2.5 | P12: 0 | Q12: 34.8 | R12: 15.6 | S12: 27.1 | T12: 18.9 | U12: 0 | V12: 0 | W12: =SUM(BDC_EAD!I$31:I$52)+SUM(BDC_EAD!I$81:I$102) -> 0.110746 | X12: =SUM(BDC_EAD!I$6:I$27)+SUM(BDC_EAD!I$56:I$77) -> 0.51562 | Y12: =MAX(0,Q12-W12) -> 34.689254 | Z12: =MAX(0,R12-(X12-W12)) -> 15.195126 | AA12: 0 | AB12: 0 | AC12: 0 | AD12: 0 | AE12: 0 | AF12: 47.15 | AG12: 104.7 | AH12: 1.1 | AI12: 204.9 | AJ12: 449.792 | AK12: 2.767 | AL12: 0 | AM12: 0.105 | AN12: =AL12*AM12 -> 0 | AO12: 0 | AP12: 0 | AQ12: 124.4 | AR12: 0 | AS12: 0.5 | AT12: 1 | AU12: 1.5 | AV12: 2 | AW12: 2 | AX12: 2 | AY12: 18.29316 | AZ12: 18.29316 | BA12: =G12/H12 -> 0.098043131 | BB12: =Holdings!$P12 -> 9.15
A13: USB | B13: U.S. Bancorp | C13: USD | D13: 0 | E13: 0 | F13: 4 | G13: 55 | H13: 508.2 | I13: 0.071 | J13: 3.258 | K13: 89.085 | L13: -4.444 | M13: 74.085 | N13: -9.463 | O13: 2.5 | P13: 0 | Q13: 14.2 | R13: 5.9 | S13: 14.4 | T13: 12.2 | U13: 0 | V13: 0 | W13: =SUM(BDC_EAD!J$31:J$52)+SUM(BDC_EAD!J$81:J$102) -> 0.359937 | X13: =SUM(BDC_EAD!J$6:J$27)+SUM(BDC_EAD!J$56:J$77) -> 1.475541 | Y13: =MAX(0,Q13-W13) -> 13.840063 | Z13: =MAX(0,R13-(X13-W13)) -> 4.784396 | AA13: 0 | AB13: 0 | AC13: 0 | AD13: 0 | AE13: 0 | AF13: 50.72 | AG13: 108.834 | AH13: 1.076 | AI13: 282.9 | AJ13: 532.066 | AK13: 37.337 | AL13: 8.77 | AM13: 0.105 | AN13: =AL13*AM13 -> 0.92085 | AO13: 0 | AP13: 1.06 | AQ13: 192.854 | AR13: 0 | AS13: 0.075 | AT13: 0.15 | AU13: 0.225 | AV13: 0.3 | AW13: 0.3 | AX13: 0.3 | AY13: 21.16665 | AZ13: 21.16665 | BA13: =G13/H13 -> 0.10822511 | BB13: =Holdings!$P13 -> 13.01
A14: TFC | B14: Truist | C14: USD | D14: 0 | E14: 0 | F14: 3 | G14: 46.3 | H14: 431.8 | I14: 0.07 | J14: 2.21 | K14: 67.651 | L14: -4.674 | M14: 46.351 | N14: -8.206 | O14: 2.5 | P14: 0 | Q14: 22.7 | R14: 19.1 | S14: 5.4 | T14: 4.3 | U14: 0 | V14: 0 | W14: =SUM(BDC_EAD!K$31:K$52)+SUM(BDC_EAD!K$81:K$102) -> 1.175366 | X14: =SUM(BDC_EAD!K$6:K$27)+SUM(BDC_EAD!K$56:K$77) -> 2.914783 | Y14: =MAX(0,Q14-W14) -> 21.524634 | Z14: =MAX(0,R14-(X14-W14)) -> 17.360583 | AA14: 0 | AB14: 0 | AC14: 0 | AD14: 0 | AE14: 0 | AF14: 51.02 | AG14: 92.8 | AH14: 1.13 | AI14: 188.3 | AJ14: 409.379 | AK14: 3.414 | AL14: 5.871 | AM14: 0.105 | AN14: =AL14*AM14 -> 0.616455 | AO14: 5.98 | AP14: 0.05 | AQ14: 108.495 | AR14: 0 | AS14: 0.0928 | AT14: 0.1856 | AU14: 0.2784 | AV14: 0.3712 | AW14: 0.464 | AX14: 0.5568 | AY14: 16.45038 | AZ14: 16.45038 | BA14: =G14/H14 -> 0.10722557 | BB14: =Holdings!$P14 -> 4.41
A15: STT | B15: State Street | C15: USD | D15: 1 | E15: 1 | F15: 5 | G15: 15.4 | H15: 140.6 | I15: 0.08 | J15: 1.389 | K15: 72.297 | L15: 0 | M15: 35.29 | N15: -4.186 | O15: 2.5 | P15: 0 | Q15: 22.3 | R15: 6.7 | S15: 10.7 | T15: 5.3 | U15: 0 | V15: 0 | W15: =SUM(BDC_EAD!L$31:L$52)+SUM(BDC_EAD!L$81:L$102) -> 0.586001 | X15: =SUM(BDC_EAD!L$6:L$27)+SUM(BDC_EAD!L$56:L$77) -> 1.995399 | Y15: =MAX(0,Q15-W15) -> 21.713999 | Z15: =MAX(0,R15-(X15-W15)) -> 5.290602 | AA15: 0 | AB15: 0 | AC15: 0 | AD15: 0 | AE15: 0 | AF15: 2.29 | AG15: 105.683 | AH15: 1.07 | AI15: 247.603 | AJ15: 319.547 | AK15: 4.372 | AL15: 0.395 | AM15: 0.14965543 | AN15: =AL15*AM15 -> 0.059113895 | AO15: 0 | AP15: 0 | AQ15: 82.79 | AR15: 0 | AS15: 0.33 | AT15: 0.66 | AU15: 0.99 | AV15: 1.32 | AW15: 1.65 | AX15: 1.65 | AY15: 103.682 | AZ15: 302.325 | BA15: =G15/H15 -> 0.10953058 | BB15: =Holdings!$P15 -> 16.07
A16: BK | B16: BNY | C16: USD | D16: 1 | E16: 1 | F16: 5 | G16: 21 | H16: 191.8 | I16: 0.085 | J16: 2.259 | K16: 107.4 | L16: -0.703 | M16: 48.239 | N16: -2.939 | O16: 2.5 | P16: 0 | Q16: 0.364 | R16: 0.385 | S16: 5.185 | T16: 3.227 | U16: 0 | V16: 0 | W16: =SUM(BDC_EAD!M$31:M$52)+SUM(BDC_EAD!M$81:M$102) -> 0.341158 | X16: =SUM(BDC_EAD!M$6:M$27)+SUM(BDC_EAD!M$56:M$77) -> 0.863781 | Y16: =MAX(0,Q16-W16) -> 0.022842 | Z16: =MAX(0,R16-(X16-W16)) -> 0 | AA16: 0 | AB16: 30.2 | AC16: 0 | AD16: 0 | AE16: 0 | AF16: 5.63 | AG16: 142 | AH16: 1.11 | AI16: 254.043 | AJ16: 370.541 | AK16: 5.217 | AL16: 26.114 | AM16: 0.16684227 | AN16: =AL16*AM16 -> 4.356919 | AO16: 0 | AP16: 0.7 | AQ16: 92 | AR16: 0 | AS16: 0.0198 | AT16: 0.0396 | AU16: 0.0594 | AV16: 0.0792 | AW16: 0.099 | AX16: 0.099 | AY16: 95.998 | AZ16: 379.653 | BA16: =G16/H16 -> 0.10948905 | BB16: =Holdings!$P16 -> 26.92
A17: FCNCA | B17: First Citizens | C17: USD | D17: 0 | E17: 0 | F17: 2 | G17: 19.885 | H17: 184.6 | I17: 0.07 | J17: 0.881 | K17: 33.983 | L17: -0.527 | M17: 9.418 | N17: -1.204 | O17: 2.5 | P17: 0 | Q17: 2.3 | R17: 1.4 | S17: 35 | T17: 13.6 | U17: 0 | V17: 0 | W17: =SUM(BDC_EAD!N$31:N$52)+SUM(BDC_EAD!N$81:N$102) -> 0.179924 | X17: =SUM(BDC_EAD!N$6:N$27)+SUM(BDC_EAD!N$56:N$77) -> 0.445406 | Y17: =MAX(0,Q17-W17) -> 2.120076 | Z17: =MAX(0,R17-(X17-W17)) -> 1.134518 | AA17: 0 | AB17: 0 | AC17: 0 | AD17: 0 | AE17: 0 | AF17: 38.81 | AG17: 59.14 | AH17: 1.1 | AI17: 65.06 | AJ17: 173.427 | AK17: 0 | AL17: 0.152 | AM17: 0.105 | AN17: =AL17*AM17 -> 0.01596 | AO17: 0 | AP17: 0 | AQ17: 30.52 | AR17: 0 | AS17: 0.05914 | AT17: 0.11828 | AU17: 0.17742 | AV17: 0.23656 | AW17: 0.2957 | AX17: 0.35484 | AY17: 7.08951 | AZ17: 7.08951 | BA17: =G17/H17 -> 0.10771939 | BB17: =Holdings!$P17 -> 0.16
A18: CFG | B18: Citizens | C18: USD | D18: 0 | E18: 0 | F18: 3 | G18: 18.7 | H18: 177.3 | I18: 0.09 | J18: 0.889 | K18: 37.448 | L18: -1.501 | M18: 7.638 | N18: -0.854 | O18: 2.5 | P18: 0 | Q18: 6.1 | R18: 3.6 | S18: 9.8 | T18: 9.8 | U18: 0 | V18: 0 | W18: =SUM(BDC_EAD!O$31:O$52)+SUM(BDC_EAD!O$81:O$102) -> 0.590632 | X18: =SUM(BDC_EAD!O$6:O$27)+SUM(BDC_EAD!O$56:O$77) -> 1.062374 | Y18: =MAX(0,Q18-W18) -> 5.509368 | Z18: =MAX(0,R18-(X18-W18)) -> 3.128258 | AA18: 0 | AB18: 0 | AC18: 0 | AD18: 0 | AE18: 0 | AF18: 26.95 | AG18: 51.3 | AH18: 1.1 | AI18: 89.617 | AJ18: 185.62 | AK18: 1.159 | AL18: 0 | AM18: 0.105 | AN18: =AL18*AM18 -> 0 | AO18: 0 | AP18: 0 | AQ18: 78.3 | AR18: 0 | AS18: 0.0513 | AT18: 0.1026 | AU18: 0.1539 | AV18: 0.2052 | AW18: 0.2565 | AX18: 0.3078 | AY18: 6.97551 | AZ18: 6.97551 | BA18: =G18/H18 -> 0.10547095 | BB18: =Holdings!$P18 -> 0.73
A19: BARC | B19: Barclays | C19: GBP | D19: 1 | E19: 1 | F19: 3 | G19: 69.21198 | H19: 483.68832 | I19: 0.122 | J19: 5.0689157 | K19: 109.68 | L19: 0 | M19: 109.68 | N19: 0 | O19: 1 | P19: 0 | Q19: 21.2144 | R19: 6.6295 | S19: 5.3036 | T19: 0 | U19: 26.518 | V19: 26.38541 | W19: =SUM(BDC_EAD!P$31:P$52)+SUM(BDC_EAD!P$81:P$102) -> 1.249667 | X19: =SUM(BDC_EAD!P$6:P$27)+SUM(BDC_EAD!P$56:P$77) -> 2.387078 | Y19: =MAX(0,Q19-W19) -> 19.964733 | Z19: =MAX(0,R19-(X19-W19)) -> 5.492089 | AA19: 70 | AB19: 114.15999 | AC19: 0 | AD19: 0 | AE19: 0 | AF19: 29.36 | AG19: 425.87908 | AH19: 1.577 | AI19: 354.62608 | AJ19: 788.05795 | AK19: 103.81797 | AL19: 243.46441 | AM19: 0.50431599 | AN19: =AL19*AM19 -> 122.783 | AO19: 30.26 | AP19: 2.82 | AQ19: 459.68953 | AR19: 0 | AS19: 1.3259 | AT19: 3.9777 | AU19: 5.96655 | AV19: 8.949825 | AW19: 11.9331 | AX19: 14.916375 | AY19: 249.38898 | AZ19: 267.2456 | BA19: =G19/H19 -> 0.14309211 | BB19: =Holdings!$P19 -> 223.18
A20: HSBA | B20: HSBC | C20: USD | D20: 1 | E20: 1 | F20: 4 | G20: 127.7 | H20: 906.4 | I20: 0.112 | J20: 10.4 | K20: 247.365 | L20: -2.4 | M20: 247.365 | N20: -2.1 | O20: 1 | P20: 0 | Q20: 16 | R20: 6 | S20: 25 | T20: 0 | U20: 21.7 | V20: 0 | W20: =SUM(BDC_EAD!Q$31:Q$52)+SUM(BDC_EAD!Q$81:Q$102) -> 0.702337 | X20: =SUM(BDC_EAD!Q$6:Q$27)+SUM(BDC_EAD!Q$56:Q$77) -> 2.011166 | Y20: =MAX(0,Q20-W20) -> 15.297663 | Z20: =MAX(0,R20-(X20-W20)) -> 4.691171 | AA20: 0 | AB20: 0 | AC20: 0 | AD20: 0 | AE20: 0 | AF20: 67.74 | AG20: 713.669 | AH20: 1.34 | AI20: 950.01 | AJ20: 1919.104 | AK20: 0 | AL20: 276.266 | AM20: 0.39857768 | AN20: =AL20*AM20 -> 110.11346 | AO20: 0 | AP20: 2.12 | AQ20: 356.8345 | AR20: 0 | AS20: 0.06 | AT20: 0.12 | AU20: 0.18 | AV20: 0.27 | AW20: 0.36 | AX20: 0.45 | AY20: 335.546 | AZ20: 314.53321 | BA20: =G20/H20 -> 0.14088703 | BB20: =Holdings!$P20 -> 327.87
A21: DBK | B21: Deutsche Bank | C21: EUR | D21: 1 | E21: 1 | F21: 5 | G21: 58.339728 | H21: 419.23224 | I21: 0.112 | J21: 3.5837963 | K21: 86.84 | L21: 0 | M21: 86.84 | N21: 0 | O21: 1 | P21: 0 | Q21: 29.57003 | R21: 8.871009 | S21: 0 | T21: 0 | U21: 34.251 | V21: 0 | W21: =SUM(BDC_EAD!R$31:R$52)+SUM(BDC_EAD!R$81:R$102) -> 2.834584 | X21: =SUM(BDC_EAD!R$6:R$27)+SUM(BDC_EAD!R$56:R$77) -> 5.561722 | Y21: =MAX(0,Q21-W21) -> 26.735446 | Z21: =MAX(0,R21-(X21-W21)) -> 6.143871 | AA21: 77.5 | AB21: 0 | AC21: 0 | AD21: 0 | AE21: 0 | AF21: 47.66 | AG21: 281.39366 | AH21: 1.4 | AI21: 297.18337 | AJ21: 797.1201 | AK21: 28.371245 | AL21: 103.15945 | AM21: 0.33448289 | AN21: =AL21*AM21 -> 34.505069 | AO21: 5.15 | AP21: 0 | AQ21: 140.69683 | AR21: 0 | AS21: 0.1838137 | AT21: 0.2420404 | AU21: 0.3630606 | AV21: 0.5445909 | AW21: 0.7261212 | AX21: 0.9076515 | AY21: 142.51526 | AZ21: 153.83927 | BA21: =G21/H21 -> 0.1391585 | BB21: =Holdings!$P21 -> 87.29
A22: BNP | B22: BNP Paribas | C22: EUR | D22: 1 | E22: 1 | F22: 6 | G22: 117.82344 | H22: 907.6515 | I22: 0.1043 | J22: 6.9700785 | K22: 176.25 | L22: 0 | M22: 176.25 | N22: 0 | O22: 1 | P22: 0 | Q22: 25.1174 | R22: 7.53522 | S22: 0 | T22: 0 | U22: 10.04696 | V22: 3.014088 | W22: =SUM(BDC_EAD!S$31:S$52)+SUM(BDC_EAD!S$81:S$102) -> 3.627251 | X22: =SUM(BDC_EAD!S$6:S$27)+SUM(BDC_EAD!S$56:S$77) -> 9.468492 | Y22: =MAX(0,Q22-W22) -> 21.490149 | Z22: =MAX(0,R22-(X22-W22)) -> 1.693979 | AA22: 90 | AB22: 0 | AC22: 0 | AD22: 0 | AE22: 0 | AF22: 85.23 | AG22: 490.931 | AH22: 1.49 | AI22: 581.39702 | AJ22: 1423.411 | AK22: 28.375812 | AL22: 503.10495 | AM22: 0.50000709 | AN22: =AL22*AM22 -> 251.55604 | AO22: 6.01 | AP22: 19.32 | AQ22: 594.8257 | AR22: 0 | AS22: 0.490931 | AT22: 0.981862 | AU22: 1.472793 | AV22: 1.963724 | AW22: 2.454655 | AX22: 2.945586 | AY22: 446.99608 | AZ22: 292.86383 | BA22: =G22/H22 -> 0.12981132 | BB22: =Holdings!$P22 -> 352.51
A23: GLE | B23: Societe Generale | C23: EUR | D23: 1 | E23: 1 | F23: 5 | G23: 61.08095 | H23: 463.5302 | I23: 0.1026 | J23: 3.3577397 | K23: 71.865 | L23: 0 | M23: 71.865 | N23: 0 | O23: 1 | P23: 0 | Q23: 12.5587 | R23: 3.76761 | S23: 3.4251 | T23: 0 | U23: 0 | V23: 0 | W23: =SUM(BDC_EAD!T$31:T$52)+SUM(BDC_EAD!T$81:T$102) -> 2.87833 | X23: =SUM(BDC_EAD!T$6:T$27)+SUM(BDC_EAD!T$56:T$77) -> 6.657164 | Y23: =MAX(0,Q23-W23) -> 9.68037 | Z23: =MAX(0,R23-(X23-W23)) -> 0 | AA23: 0 | AB23: 0 | AC23: 0 | AD23: 0 | AE23: 0 | AF23: 32.46 | AG23: 300.2671 | AH23: 1.46 | AI23: 275.14274 | AJ23: 611.4283 | AK23: 0 | AL23: 185.3824 | AM23: 0.53237246 | AN23: =AL23*AM23 -> 98.692483 | AO23: 3.8 | AP23: 9.76 | AQ23: 363.0606 | AR23: 0 | AS23: 0.3002671 | AT23: 0.6005342 | AU23: 0.9008013 | AV23: 1.2010684 | AW23: 1.5013355 | AX23: 1.8016026 | AY23: 298.46974 | AZ23: 265.24883 | BA23: =G23/H23 -> 0.1317734 | BB23: =Holdings!$P23 -> 163.63
A24: UBS | B24: UBS | C24: USD | D24: 1 | E24: 1 | F24: 4 | G24: 72.464 | H24: 503.9 | I24: 0.1083 | J24: 3.714 | K24: 30.925 | L24: 0 | M24: 30.925 | N24: 0 | O24: 1 | P24: 0 | Q24: 0 | R24: 0 | S24: 0 | T24: 0 | U24: 0 | V24: 0 | W24: =SUM(BDC_EAD!U$31:U$52)+SUM(BDC_EAD!U$81:U$102) -> 0.023394 | X24: =SUM(BDC_EAD!U$6:U$27)+SUM(BDC_EAD!U$56:U$77) -> 0.12931 | Y24: =MAX(0,Q24-W24) -> 0 | Z24: =MAX(0,R24-(X24-W24)) -> 0 | AA24: 0 | AB24: 0 | AC24: 0 | AD24: 0 | AE24: 0 | AF24: 93.13 | AG24: 341.8 | AH24: 1.773 | AI24: 365.4855 | AJ24: 812.19 | AK24: 44.031 | AL24: 20.449 | AM24: 0.8 | AN24: =AL24*AM24 -> 16.3592 | AO24: 6.29 | AP24: 0.3 | AQ24: 170.9 | AR24: 0 | AS24: 0.3418 | AT24: 0.6836 | AU24: 1.0254 | AV24: 1.3672 | AW24: 1.709 | AX24: 2.0508 | AY24: 325.18089 | AZ24: 467.59331 | BA24: =G24/H24 -> 0.14380631 | BB24: =Holdings!$P24 -> 255.77
A25: MUFG | B25: MUFG | C25: JPY | D25: 1 | E25: 1 | F25: 4 | G25: 99.637784 | H25: 768.83771 | I25: 0.0869 | J25: 5.0113769 | K25: 229.915 | L25: -2.873132 | M25: 229.915 | N25: -7.7301519 | O25: 1 | P25: 26.136074 | Q25: 26.443638 | R25: 13.221819 | S25: 26.443638 | T25: 13.221819 | U25: 0 | V25: 0 | W25: =SUM(BDC_EAD!V$31:V$52)+SUM(BDC_EAD!V$81:V$102) -> 2.817403 | X25: =SUM(BDC_EAD!V$6:V$27)+SUM(BDC_EAD!V$56:V$77) -> 6.21229 | Y25: =MAX(0,Q25-W25) -> 23.626235 | Z25: =MAX(0,R25-(X25-W25)) -> 9.8269321 | AA25: 0 | AB25: 0 | AC25: 0 | AD25: 0 | AE25: 0 | AF25: 95.94 | AG25: 759.07233 | AH25: 1.404 | AI25: 760.7536 | AJ25: 1603.5628 | AK25: 111.41472 | AL25: 250.71151 | AM25: 0.23327164 | AN25: =AL25*AM25 -> 58.483885 | AO25: 32.9 | AP25: 2.79 | AQ25: 379.53617 | AR25: 0 | AS25: 0.20447697 | AT25: 0.40895394 | AU25: 0.61343091 | AV25: 0.81790788 | AW25: 0.81790788 | AX25: 0.81790788 | AY25: 336.47062 | AZ25: 227.19185 | BA25: =G25/H25 -> 0.12959534 | BB25: =Holdings!$P25 -> 139.9
A26: SMFG | B26: SMFG | C26: JPY | D26: 1 | E26: 1 | F26: 4 | G26: 79.337931 | H26: 628.05609 | I26: 0.0817 | J26: 4.4419162 | K26: 100.925 | L26: -1.9623639 | M26: 100.925 | N26: -1.65119 | O26: 1 | P26: 24.684171 | Q26: 8.3635693 | R26: 2.0908923 | S26: 8.3635693 | T26: 2.0908923 | U26: 0 | V26: 0 | W26: =SUM(BDC_EAD!W$31:W$52)+SUM(BDC_EAD!W$81:W$102) -> 1.537808 | X26: =SUM(BDC_EAD!W$6:W$27)+SUM(BDC_EAD!W$56:W$77) -> 4.668771 | Y26: =MAX(0,Q26-W26) -> 6.8257613 | Z26: =MAX(0,R26-(X26-W26)) -> 0 | AA26: 0 | AB26: 0 | AC26: 0 | AD26: 0 | AE26: 0 | AF26: 43.5 | AG26: 597.48935 | AH26: 1.383 | AI26: 579.37209 | AJ26: 1241.8082 | AK26: 142.21343 | AL26: 148.67816 | AM26: 0.15706172 | AN26: =AL26*AM26 -> 23.351648 | AO26: 24.02 | AP26: 0.78 | AQ26: 298.74467 | AR26: 0 | AS26: 0.59748935 | AT26: 1.1949787 | AU26: 1.792468 | AV26: 2.3899574 | AW26: 2.9874467 | AX26: 3.5849361 | AY26: 385.17425 | AZ26: 154.78467 | BA26: =G26/H26 -> 0.126323 | BB26: =Holdings!$P26 -> 37.61
A27: MFG | B27: Mizuho | C27: JPY | D27: 1 | E27: 1 | F27: 4 | G27: 68.322981 | H27: 505.58822 | I27: 0.0813 | J27: 3.2740914 | K27: 85.305 | L27: 0 | M27: 85.305 | N27: -0.91138306 | O27: 1 | P27: 18.386938 | Q27: 7.3333333 | R27: 3.6666667 | S27: 14.666667 | T27: 7.3333333 | U27: 0 | V27: 0 | W27: =SUM(BDC_EAD!X$31:X$52)+SUM(BDC_EAD!X$81:X$102) -> 0.411154 | X27: =SUM(BDC_EAD!X$6:X$27)+SUM(BDC_EAD!X$56:X$77) -> 1.469927 | Y27: =MAX(0,Q27-W27) -> 6.9221793 | Z27: =MAX(0,R27-(X27-W27)) -> 2.6078937 | AA27: 0 | AB27: 0 | AC27: 0 | AD27: 0 | AE27: 0 | AF27: 0 | AG27: 503.44704 | AH27: 1.261 | AI27: 556.83606 | AJ27: 1101.0295 | AK27: 37.602503 | AL27: 244.75177 | AM27: 0.22397089 | AN27: =AL27*AM27 -> 54.817273 | AO27: 15.5 | AP27: 7.29 | AQ27: 251.72352 | AR27: 0 | AS27: 0.58421991 | AT27: 1.1684398 | AU27: 1.7526597 | AV27: 2.3368797 | AW27: 2.3368797 | AX27: 2.3368797 | AY27: 116.0015 | AZ27: 130.77673 | BA27: =G27/H27 -> 0.13513563 | BB27: =Holdings!$P27 -> 49.24
A28: RY | B28: RBC | C28: CAD | D28: 1 | E28: 1 | F28: 5 | G28: 73.88666 | H28: 547.69447 | I28: 0.111 | J28: 6.1590989 | K28: 158.98 | L28: -0.22527279 | M28: 158.98 | N28: -2.2379444 | O28: 1 | P28: 0 | Q28: 10.770855 | R28: 0 | S28: 0 | T28: 0 | U28: 23.935234 | V28: 0 | W28: =SUM(BDC_EAD!Y$31:Y$52)+SUM(BDC_EAD!Y$81:Y$102) -> 1.193217 | X28: =SUM(BDC_EAD!Y$6:Y$27)+SUM(BDC_EAD!Y$56:Y$77) -> 3.950015 | Y28: =MAX(0,Q28-W28) -> 9.5776383 | Z28: =MAX(0,R28-(X28-W28)) -> 0 | AA28: 0 | AB28: 0 | AC28: 0 | AD28: 0 | AE28: 0 | AF28: 78.23 | AG28: 342.73214 | AH28: 1.25 | AI28: 381.63393 | AJ28: 1157.7423 | AK28: 111.12284 | AL28: 228.92291 | AM28: 0.29868984 | AN28: =AL28*AM28 -> 68.376949 | AO28: 38.53 | AP28: 2.13 | AQ28: 440.38508 | AR28: 0 | AS28: 0.29567054 | AT28: 0.45406547 | AU28: 0.71312918 | AV28: 1.0696938 | AW28: 1.4262584 | AX28: 1.7828229 | AY28: 138.14253 | AZ28: 111.7711 | BA28: =G28/H28 -> 0.13490488 | BB28: =Holdings!$P28 -> 135.42
A29: JEF | B29: Jefferies | C29: USD | D29: 0 | E29: 1 | F29: 2 | G29: 8.718 | H29: 96.866667 | I29: 0.0675 | J29: 0.351 | K29: 0 | L29: 0 | M29: 0 | N29: 0 | O29: 0 | P29: 0 | Q29: 0 | R29: 0 | S29: 0 | T29: 0 | U29: 0 | V29: 0 | W29: =SUM(BDC_EAD!Z$31:Z$52)+SUM(BDC_EAD!Z$81:Z$102) -> 0 | X29: =SUM(BDC_EAD!Z$6:Z$27)+SUM(BDC_EAD!Z$56:Z$77) -> 0 | Y29: =MAX(0,Q29-W29) -> 0 | Z29: =MAX(0,R29-(X29-W29)) -> 0 | AA29: 0 | AB29: 0 | AC29: 0 | AD29: 0 | AE29: 0 | AF29: 0 | AG29: 17.238 | AH29: 1 | AI29: 0 | AJ29: 0 | AK29: 1.603 | AL29: 16.734 | AM29: 0.72828685 | AN29: =AL29*AM29 -> 12.187152 | AO29: 0 | AP29: 0 | AQ29: 3.61 | AR29: 0 | AS29: 0.44985 | AT29: 0.8997 | AU29: 0.8997 | AV29: 0.8997 | AW29: 0.8997 | AX29: 0.8997 | AY29: 12.225 | AZ29: 12.225 | BA29: =G29/H29 -> 0.09 | BB29: =Holdings!$P29 -> 18.28

Sheet Holdings
A1: Holdings by asset class (USD bn) and fire-sale parameters
A2: Rows 31-39: price-impact lambda (bp of price per $bn sold, before dealer multiplier), capital-relevant net fraction, saleable flag, discount cap, fundamental price decline (scenario), non-bank seller allocation, panic discount at full panic (S = 1; correlation-to-1 repricing of every risky class).
A5: Id | B5: Institution | C5: UST | D5: AGENCY_MBS | E5: OTHER_SOV | F5: MUNI | G5: IG_CORP | H5: HY_CORP | I5: LEV_LOANS | J5: CLO | K5: ABS_OTHER | L5: PRIV_CREDIT_LOANS | M5: EQUITIES | N5: CRE_LOANS | O5: OTHER | P5: Saleable total | Q5: w UST | R5: w AGENCY_MBS | S5: w OTHER_SOV | T5: w MUNI | U5: w IG_CORP | V5: w HY_CORP | W5: w LEV_LOANS | X5: w CLO | Y5: w ABS_OTHER | Z5: w PRIV_CREDIT_LOANS | AA5: w EQUITIES | AB5: w CRE_LOANS | AC5: w OTHER
A6: JPM | B6: JPMorgan | C6: 726.55 | D6: 349.32 | E6: 242.69 | F6: 34 | G6: 55.56 | H6: 0 | I6: 14.24 | J6: 44.03 | K6: 33.98 | L6: 0 | M6: 267.07 | N6: 180.31 | O6: 31.39 | P6: =SUMPRODUCT(C6:O6,$C$33:$O$33) -> 480.27 | Q6: =IF($P6>0,C6*C$33/$P6,0) -> 0 | R6: =IF($P6>0,D6*D$33/$P6,0) -> 0 | S6: =IF($P6>0,E6*E$33/$P6,0) -> 0 | T6: =IF($P6>0,F6*F$33/$P6,0) -> 0.070793512 | U6: =IF($P6>0,G6*G$33/$P6,0) -> 0.11568493 | V6: =IF($P6>0,H6*H$33/$P6,0) -> 0 | W6: =IF($P6>0,I6*I$33/$P6,0) -> 0.029649989 | X6: =IF($P6>0,J6*J$33/$P6,0) -> 0.091677598 | ... AC6: =IF($P6>0,O6*O$33/$P6,0) -> 0.065359069
A7: BAC | B7: Bank of America | C7: 375.38 | D7: 528.24 | E7: 111.71 | F7: 14.32 | G7: 45.65 | H7: 0 | I7: 6.9 | J7: 8.75 | K7: 14.76 | L7: 0 | M7: 120.67 | N7: 83.31 | O7: 0 | P7: =SUMPRODUCT(C7:O7,$C$33:$O$33) -> 211.05 | Q7: =IF($P7>0,C7*C$33/$P7,0) -> 0 | R7: =IF($P7>0,D7*D$33/$P7,0) -> 0 | S7: =IF($P7>0,E7*E$33/$P7,0) -> 0 | T7: =IF($P7>0,F7*F$33/$P7,0) -> 0.06785122 | U7: =IF($P7>0,G7*G$33/$P7,0) -> 0.21629946 | V7: =IF($P7>0,H7*H$33/$P7,0) -> 0 | W7: =IF($P7>0,I7*I$33/$P7,0) -> 0.032693674 | X7: =IF($P7>0,J7*J$33/$P7,0) -> 0.04145937 | ... AC7: =IF($P7>0,O7*O$33/$P7,0) -> 0
A8: C | B8: Citigroup | C8: 280.64 | D8: 221.97 | E8: 321.85 | F8: 9.97 | G8: 31.57 | H8: 0 | I8: 1.45 | J8: 18.23 | K8: 8.48 | L8: 0 | M8: 97.93 | N8: 37.19 | O8: 30.87 | P8: =SUMPRODUCT(C8:O8,$C$33:$O$33) -> 198.5 | Q8: =IF($P8>0,C8*C$33/$P8,0) -> 0 | R8: =IF($P8>0,D8*D$33/$P8,0) -> 0 | S8: =IF($P8>0,E8*E$33/$P8,0) -> 0 | T8: =IF($P8>0,F8*F$33/$P8,0) -> 0.0502267 | U8: =IF($P8>0,G8*G$33/$P8,0) -> 0.15904282 | V8: =IF($P8>0,H8*H$33/$P8,0) -> 0 | W8: =IF($P8>0,I8*I$33/$P8,0) -> 0.0073047859 | X8: =IF($P8>0,J8*J$33/$P8,0) -> 0.091838791 | ... AC8: =IF($P8>0,O8*O$33/$P8,0) -> 0.15551637
A9: WFC | B9: Wells Fargo | C9: 148.35 | D9: 391.16 | E9: 0.33 | F9: 29.87 | G9: 17.09 | H9: 0 | I9: 5.03 | J9: 13.21 | K9: 5.26 | L9: 0 | M9: 37.96 | N9: 126.02 | O9: 19.32 | P9: =SUMPRODUCT(C9:O9,$C$33:$O$33) -> 127.74 | Q9: =IF($P9>0,C9*C$33/$P9,0) -> 0 | R9: =IF($P9>0,D9*D$33/$P9,0) -> 0 | S9: =IF($P9>0,E9*E$33/$P9,0) -> 0 | T9: =IF($P9>0,F9*F$33/$P9,0) -> 0.23383435 | U9: =IF($P9>0,G9*G$33/$P9,0) -> 0.13378738 | V9: =IF($P9>0,H9*H$33/$P9,0) -> 0 | W9: =IF($P9>0,I9*I$33/$P9,0) -> 0.039376859 | X9: =IF($P9>0,J9*J$33/$P9,0) -> 0.10341318 | ... AC9: =IF($P9>0,O9*O$33/$P9,0) -> 0.15124472
A10: GS | B10: Goldman Sachs | C10: 392.14 | D10: 76.82 | E10: 151.26 | F10: 0.89 | G10: 67.92 | H10: 0 | I10: 23.81 | J10: 0 | K10: 23.07 | L10: 0 | M10: 247.17 | N10: 40.31 | O10: 4.11 | P10: =SUMPRODUCT(C10:O10,$C$33:$O$33) -> 366.97 | Q10: =IF($P10>0,C10*C$33/$P10,0) -> 0 | R10: =IF($P10>0,D10*D$33/$P10,0) -> 0 | S10: =IF($P10>0,E10*E$33/$P10,0) -> 0 | T10: =IF($P10>0,F10*F$33/$P10,0) -> 0.0024252664 | U10: =IF($P10>0,G10*G$33/$P10,0) -> 0.18508325 | V10: =IF($P10>0,H10*H$33/$P10,0) -> 0 | W10: =IF($P10>0,I10*I$33/$P10,0) -> 0.064882688 | X10: =IF($P10>0,J10*J$33/$P10,0) -> 0 | ... AC10: =IF($P10>0,O10*O$33/$P10,0) -> 0.011199826
A11: MS | B11: Morgan Stanley | C11: 161.79 | D11: 136.84 | E11: 64.29 | F11: 6.51 | G11: 46.68 | H11: 0 | I11: 24.16 | J11: 0 | K11: 5.23 | L11: 0 | M11: 211.99 | N11: 16.4 | O11: 3.41 | P11: =SUMPRODUCT(C11:O11,$C$33:$O$33) -> 297.98 | Q11: =IF($P11>0,C11*C$33/$P11,0) -> 0 | R11: =IF($P11>0,D11*D$33/$P11,0) -> 0 | S11: =IF($P11>0,E11*E$33/$P11,0) -> 0 | T11: =IF($P11>0,F11*F$33/$P11,0) -> 0.021847104 | U11: =IF($P11>0,G11*G$33/$P11,0) -> 0.15665481 | V11: =IF($P11>0,H11*H$33/$P11,0) -> 0 | W11: =IF($P11>0,I11*I$33/$P11,0) -> 0.081079267 | X11: =IF($P11>0,J11*J$33/$P11,0) -> 0 | ... AC11: =IF($P11>0,O11*O$33/$P11,0) -> 0.011443721
A12: PNC | B12: PNC | C12: 46.42 | D12: 96.53 | E12: 0.06 | F12: 2.37 | G12: 2.02 | H12: 0 | I12: 0.02 | J12: 0.06 | K12: 4.68 | L12: 0 | M12: 0 | N12: 47.15 | O12: 0 | P12: =SUMPRODUCT(C12:O12,$C$33:$O$33) -> 9.15 | Q12: =IF($P12>0,C12*C$33/$P12,0) -> 0 | R12: =IF($P12>0,D12*D$33/$P12,0) -> 0 | S12: =IF($P12>0,E12*E$33/$P12,0) -> 0 | T12: =IF($P12>0,F12*F$33/$P12,0) -> 0.25901639 | U12: =IF($P12>0,G12*G$33/$P12,0) -> 0.22076503 | V12: =IF($P12>0,H12*H$33/$P12,0) -> 0 | W12: =IF($P12>0,I12*I$33/$P12,0) -> 0.0021857923 | X12: =IF($P12>0,J12*J$33/$P12,0) -> 0.006557377 | ... AC12: =IF($P12>0,O12*O$33/$P12,0) -> 0
A13: USB | B13: U.S. Bancorp | C13: 24.09 | D13: 125.09 | E13: 0.42 | F13: 7.38 | G13: 0 | H13: 0 | I13: 0.09 | J13: 4.38 | K13: 1.16 | L13: 0 | M13: 0 | N13: 50.72 | O13: 0 | P13: =SUMPRODUCT(C13:O13,$C$33:$O$33) -> 13.01 | Q13: =IF($P13>0,C13*C$33/$P13,0) -> 0 | R13: =IF($P13>0,D13*D$33/$P13,0) -> 0 | S13: =IF($P13>0,E13*E$33/$P13,0) -> 0 | T13: =IF($P13>0,F13*F$33/$P13,0) -> 0.56725596 | U13: =IF($P13>0,G13*G$33/$P13,0) -> 0 | V13: =IF($P13>0,H13*H$33/$P13,0) -> 0 | W13: =IF($P13>0,I13*I$33/$P13,0) -> 0.0069177556 | X13: =IF($P13>0,J13*J$33/$P13,0) -> 0.3366641 | ... AC13: =IF($P13>0,O13*O$33/$P13,0) -> 0
A14: TFC | B14: Truist | C14: 13.12 | D14: 99.11 | E14: 0 | F14: 0.34 | G14: 0 | H14: 0 | I14: 0.17 | J14: 0 | K14: 1.28 | L14: 0 | M14: 0 | N14: 51.02 | O14: 2.62 | P14: =SUMPRODUCT(C14:O14,$C$33:$O$33) -> 4.41 | Q14: =IF($P14>0,C14*C$33/$P14,0) -> 0 | R14: =IF($P14>0,D14*D$33/$P14,0) -> 0 | S14: =IF($P14>0,E14*E$33/$P14,0) -> 0 | T14: =IF($P14>0,F14*F$33/$P14,0) -> 0.077097506 | U14: =IF($P14>0,G14*G$33/$P14,0) -> 0 | V14: =IF($P14>0,H14*H$33/$P14,0) -> 0 | W14: =IF($P14>0,I14*I$33/$P14,0) -> 0.038548753 | X14: =IF($P14>0,J14*J$33/$P14,0) -> 0 | ... AC14: =IF($P14>0,O14*O$33/$P14,0) -> 0.59410431
A15: STT | B15: State Street | C15: 24.3 | D15: 43.05 | E15: 23.96 | F15: 0.03 | G15: 0.12 | H15: 0 | I15: 0 | J15: 4.01 | K15: 11.79 | L15: 0 | M15: 0 | N15: 2.29 | O15: 0.12 | P15: =SUMPRODUCT(C15:O15,$C$33:$O$33) -> 16.07 | Q15: =IF($P15>0,C15*C$33/$P15,0) -> 0 | R15: =IF($P15>0,D15*D$33/$P15,0) -> 0 | S15: =IF($P15>0,E15*E$33/$P15,0) -> 0 | T15: =IF($P15>0,F15*F$33/$P15,0) -> 0.0018668326 | U15: =IF($P15>0,G15*G$33/$P15,0) -> 0.0074673304 | V15: =IF($P15>0,H15*H$33/$P15,0) -> 0 | W15: =IF($P15>0,I15*I$33/$P15,0) -> 0 | X15: =IF($P15>0,J15*J$33/$P15,0) -> 0.24953329 | ... AC15: =IF($P15>0,O15*O$33/$P15,0) -> 0.0074673304
A16: BK | B16: BNY | C16: 36.02 | D16: 65.47 | E16: 32.94 | F16: 0.01 | G16: 8.57 | H16: 0 | I16: 0 | J16: 8.85 | K16: 3.8 | L16: 0 | M16: 0 | N16: 5.63 | O16: 5.69 | P16: =SUMPRODUCT(C16:O16,$C$33:$O$33) -> 26.92 | Q16: =IF($P16>0,C16*C$33/$P16,0) -> 0 | R16: =IF($P16>0,D16*D$33/$P16,0) -> 0 | S16: =IF($P16>0,E16*E$33/$P16,0) -> 0 | T16: =IF($P16>0,F16*F$33/$P16,0) -> 0.00037147103 | U16: =IF($P16>0,G16*G$33/$P16,0) -> 0.31835067 | V16: =IF($P16>0,H16*H$33/$P16,0) -> 0 | W16: =IF($P16>0,I16*I$33/$P16,0) -> 0 | X16: =IF($P16>0,J16*J$33/$P16,0) -> 0.32875186 | ... AC16: =IF($P16>0,O16*O$33/$P16,0) -> 0.21136701
A17: FCNCA | B17: First Citizens | C17: 13.71 | D17: 29.29 | E17: 0.25 | F17: 0.01 | G17: 0.13 | H17: 0 | I17: 0 | J17: 0 | K17: 0.02 | L17: 0 | M17: 0 | N17: 38.81 | O17: 0 | P17: =SUMPRODUCT(C17:O17,$C$33:$O$33) -> 0.16 | Q17: =IF($P17>0,C17*C$33/$P17,0) -> 0 | R17: =IF($P17>0,D17*D$33/$P17,0) -> 0 | S17: =IF($P17>0,E17*E$33/$P17,0) -> 0 | T17: =IF($P17>0,F17*F$33/$P17,0) -> 0.0625 | U17: =IF($P17>0,G17*G$33/$P17,0) -> 0.8125 | V17: =IF($P17>0,H17*H$33/$P17,0) -> 0 | W17: =IF($P17>0,I17*I$33/$P17,0) -> 0 | X17: =IF($P17>0,J17*J$33/$P17,0) -> 0 | ... AC17: =IF($P17>0,O17*O$33/$P17,0) -> 0
... A29: JEF | B29: Jefferies | C29: 3.11 | D29: 2.02 | E29: 1.69 | F29: 0.65 | G29: 5.27 | H29: 0 | I29: 1.83 | J29: 0.71 | K29: 0.98 | L29: 0 | M29: 8.66 | N29: 0 | O29: 0.18 | P29: =SUMPRODUCT(C29:O29,$C$33:$O$33) -> 18.28 | Q29: =IF($P29>0,C29*C$33/$P29,0) -> 0 | R29: =IF($P29>0,D29*D$33/$P29,0) -> 0 | S29: =IF($P29>0,E29*E$33/$P29,0) -> 0 | T29: =IF($P29>0,F29*F$33/$P29,0) -> 0.035557987 | U29: =IF($P29>0,G29*G$33/$P29,0) -> 0.28829322 | V29: =IF($P29>0,H29*H$33/$P29,0) -> 0 | W29: =IF($P29>0,I29*I$33/$P29,0) -> 0.10010941 | X29: =IF($P29>0,J29*J$33/$P29,0) -> 0.038840263 | ... AC29: =IF($P29>0,O29*O$33/$P29,0) -> 0.0098468271
B31: Lambda (bp per $bn) | C31: 0.02 | D31: 0.06 | E31: 0.3 | F31: 0.25 | G31: 0.75 | H31: 1.5 | I31: 3 | J31: 3 | K31: 1.5 | L31: 3 | M31: 0.05 | N31: 3 | O31: 1
B32: Net fraction hitting capital | C32: 0.1 | D32: 0.1 | E32: 0.1 | F32: 0.25 | G32: 0.25 | H32: 0.5 | I32: 1 | J32: 0.5 | K32: 0.5 | L32: 0 | M32: 0.02 | N32: 0 | O32: 0.1
B33: Saleable (1/0) | C33: 0 | D33: 0 | E33: 0 | F33: 1 | G33: 1 | H33: 1 | I33: 1 | J33: 1 | K33: 1 | L33: 0 | M33: 1 | N33: 0 | O33: 1
B34: Cap on fire-sale discount | C34: 0.05 | D34: 0.05 | E34: 0.1 | F34: 0.2 | G34: 0.25 | H34: 0.35 | I34: 0.45 | J34: 0.45 | K34: 0.4 | L34: 0.45 | M34: 0.4 | N34: 0.3 | O34: 0.3
B35: Fundamental price decline (scenario) | C35: 0 | D35: 0 | E35: =-p_dp_OSOV -> 0.02 | F35: =-p_dp_MUNI -> 0.06 | G35: =-p_dp_IG -> 0.08 | H35: =-p_dp_HY -> 0.25 | I35: =-p_dp_LEV -> 0.3 | J35: =-p_dp_CLO -> 0.25 | K35: =-p_dp_ABS -> 0.2 | L35: 0 | M35: =-p_dp_EQ -> 0.45 | N35: 0 | O35: 0
B36: Matched-book client sale allocation | C36: 0 | D36: 0 | E36: 0 | F36: 0.03 | G36: 0.25 | H36: 0.11 | I36: 0 | J36: 0 | K36: 0.13 | L36: 0 | M36: 0.48 | N36: 0 | O36: 0
B37: Insurer sale allocation | C37: 0 | D37: 0 | E37: 0 | F37: 0 | G37: 0.5 | H37: 0 | I37: 0 | J37: 0.2 | K37: 0.15 | L37: 0.15 | M37: 0 | N37: 0 | O37: 0
B38: Non-bank sales ($bn, round-invariant) | C38: =CE_ins_sales*C37 -> 0 | D38: =CE_ins_sales*D37 -> 0 | E38: =CE_ins_sales*E37 -> 0 | F38: =CE_ins_sales*F37 -> 0 | G38: =CE_ins_sales*G37 -> 14.78125 | H38: =CE_ins_sales*H37 -> 0 | I38: =CE_ins_sales*I37 -> 0 | J38: =CE_ins_sales*J37 -> 5.9125 | K38: =CE_ins_sales*K37 -> 4.434375 | L38: =CE_ins_sales*L37+CE_nonbank_pcl -> 151.83355 | M38: =CE_ins_sales*M37 -> 0 | N38: =CE_ins_sales*N37 -> 0 | O38: =CE_ins_sales*O37 -> 0
B39: Panic discount at full panic (S = 1) | C39: 0 | D39: 0.01 | E39: 0.02 | F39: 0.08 | G39: 0.1 | H39: 0.15 | I39: 0.2 | J39: 0.15 | K39: 0.1 | L39: 0.2 | M39: 0.3 | N39: 0 | O39: 0.1
B40: Basis | C40: Cont-Schaanning UST 0.23bp/EUR10bn; no panic discount (flight to quality) | D40: Duarte-Eisenbach agency = 3x UST | E40: Cont-Schaanning EU sovereigns 4.6-13bp/EUR10bn | F40: Duarte-Eisenbach munis = 12x UST; panic: judgment | G40: Ellul et al. 7.5bp per $10bn; panic: judgment, March-2020 scale | H40: Judgment: 2x IG; panic: March-2020 scale | I40: Calibration judgment; panic: LLI 76.23 on 23-Mar-2020 | J40: Calibration judgment (as loans) | K40: Judgment: between IG and loans | L40: Judgment (as loans); enters M1/M10 via pool liquidation value | M40: Judgment: deep market; dealer equity inventory delta-hedged (net 2%); panic: S&P -34% Feb-Mar 2020 scale | N40: Judgment; CRE losses in M7 | O40: Judgment
